INFO:     Will watch for changes in these directories: ['/root/DataCenter']
INFO:     Uvicorn running on http://0.0.0.0:13833 (Press CTRL+C to quit)
INFO:     Started reloader process [28151] using StatReload
Process SpawnProcess-1:
Traceback (most recent call last):
  File "/usr/lib64/python3.9/multiprocessing/process.py", line 315, in _bootstrap
    self.run()
  File "/usr/lib64/python3.9/multiprocessing/process.py", line 108, in run
    self._target(*self._args, **self._kwargs)
  File "/root/DataCenter/DataCenter_Venv/lib64/python3.9/site-packages/uvicorn/_subprocess.py", line 80, in subprocess_started
    target(sockets=sockets)
  File "/root/DataCenter/DataCenter_Venv/lib64/python3.9/site-packages/uvicorn/server.py", line 67, in run
    return asyncio.run(self.serve(sockets=sockets))
  File "/usr/lib64/python3.9/asyncio/runners.py", line 44, in run
    return loop.run_until_complete(main)
  File "/usr/lib64/python3.9/asyncio/base_events.py", line 647, in run_until_complete
    return future.result()
  File "/root/DataCenter/DataCenter_Venv/lib64/python3.9/site-packages/uvicorn/server.py", line 71, in serve
    await self._serve(sockets)
  File "/root/DataCenter/DataCenter_Venv/lib64/python3.9/site-packages/uvicorn/server.py", line 78, in _serve
    config.load()
  File "/root/DataCenter/DataCenter_Venv/lib64/python3.9/site-packages/uvicorn/config.py", line 436, in load
    self.loaded_app = import_from_string(self.app)
  File "/root/DataCenter/DataCenter_Venv/lib64/python3.9/site-packages/uvicorn/importer.py", line 19, in import_from_string
    module = importlib.import_module(module_str)
  File "/usr/lib64/python3.9/importlib/__init__.py", line 127, in import_module
    return _bootstrap._gcd_import(name[level:], package, level)
  File "<frozen importlib._bootstrap>", line 1030, in _gcd_import
  File "<frozen importlib._bootstrap>", line 1007, in _find_and_load
  File "<frozen importlib._bootstrap>", line 986, in _find_and_load_unlocked
  File "<frozen importlib._bootstrap>", line 680, in _load_unlocked
  File "<frozen importlib._bootstrap_external>", line 850, in exec_module
  File "<frozen importlib._bootstrap>", line 228, in _call_with_frames_removed
  File "/root/DataCenter/app.py", line 2, in <module>
    from AI_API.home import router as apiRouter
  File "/root/DataCenter/AI_API/home.py", line 1, in <module>
    from AI_API.gptUsage import getGptUsage
ImportError: cannot import name 'getGptUsage' from 'AI_API.gptUsage' (/root/DataCenter/AI_API/gptUsage.py)
WARNING:  StatReload detected changes in 'AI_API/home.py'. Reloading...
INFO:     Started server process [28503]
INFO:     Waiting for application startup.
INFO:     Application startup complete.
WARNING:  StatReload detected changes in 'AI_API/gptUsage.py'. Reloading...
INFO:     Shutting down
INFO:     Waiting for application shutdown.
INFO:     Application shutdown complete.
INFO:     Finished server process [28503]
INFO:     Started server process [28524]
INFO:     Waiting for application startup.
INFO:     Application startup complete.
INFO:     119.147.10.159:50864 - "GET /docs HTTP/1.1" 200 OK
INFO:     119.147.10.159:50864 - "GET /openapi.json HTTP/1.1" 200 OK
INFO:     119.147.10.159:54606 - "GET /apiUsage HTTP/1.1" 200 OK
WARNING:  StatReload detected changes in 'AI_API/gptUsage.py'. Reloading...
INFO:     Shutting down
INFO:     Waiting for application shutdown.
INFO:     Application shutdown complete.
INFO:     Finished server process [28524]
INFO:     Started server process [29455]
INFO:     Waiting for application startup.
INFO:     Application startup complete.
WARNING:  StatReload detected changes in 'AI_API/home.py'. Reloading...
INFO:     Shutting down
INFO:     Waiting for application shutdown.
INFO:     Application shutdown complete.
INFO:     Finished server process [29455]
INFO:     Started server process [29500]
INFO:     Waiting for application startup.
INFO:     Application startup complete.
WARNING:  StatReload detected changes in 'AI_API/gptUsage.py'. Reloading...
INFO:     Shutting down
INFO:     Waiting for application shutdown.
INFO:     Application shutdown complete.
INFO:     Finished server process [29500]
INFO:     Started server process [30458]
INFO:     Waiting for application startup.
INFO:     Application startup complete.
WARNING:  StatReload detected changes in 'config.py'. Reloading...
INFO:     Shutting down
INFO:     Waiting for application shutdown.
INFO:     Application shutdown complete.
INFO:     Finished server process [30458]
INFO:     Started server process [33565]
INFO:     Waiting for application startup.
INFO:     Application startup complete.
WARNING:  StatReload detected changes in 'AI_API/gptUsage.py'. Reloading...
INFO:     Shutting down
INFO:     Waiting for application shutdown.
INFO:     Application shutdown complete.
INFO:     Finished server process [33565]
Process SpawnProcess-8:
Traceback (most recent call last):
  File "/usr/lib64/python3.9/multiprocessing/process.py", line 315, in _bootstrap
    self.run()
  File "/usr/lib64/python3.9/multiprocessing/process.py", line 108, in run
    self._target(*self._args, **self._kwargs)
  File "/root/DataCenter/DataCenter_Venv/lib64/python3.9/site-packages/uvicorn/_subprocess.py", line 80, in subprocess_started
    target(sockets=sockets)
  File "/root/DataCenter/DataCenter_Venv/lib64/python3.9/site-packages/uvicorn/server.py", line 67, in run
    return asyncio.run(self.serve(sockets=sockets))
  File "/usr/lib64/python3.9/asyncio/runners.py", line 44, in run
    return loop.run_until_complete(main)
  File "/usr/lib64/python3.9/asyncio/base_events.py", line 647, in run_until_complete
    return future.result()
  File "/root/DataCenter/DataCenter_Venv/lib64/python3.9/site-packages/uvicorn/server.py", line 71, in serve
    await self._serve(sockets)
  File "/root/DataCenter/DataCenter_Venv/lib64/python3.9/site-packages/uvicorn/server.py", line 78, in _serve
    config.load()
  File "/root/DataCenter/DataCenter_Venv/lib64/python3.9/site-packages/uvicorn/config.py", line 436, in load
    self.loaded_app = import_from_string(self.app)
  File "/root/DataCenter/DataCenter_Venv/lib64/python3.9/site-packages/uvicorn/importer.py", line 22, in import_from_string
    raise exc from None
  File "/root/DataCenter/DataCenter_Venv/lib64/python3.9/site-packages/uvicorn/importer.py", line 19, in import_from_string
    module = importlib.import_module(module_str)
  File "/usr/lib64/python3.9/importlib/__init__.py", line 127, in import_module
    return _bootstrap._gcd_import(name[level:], package, level)
  File "<frozen importlib._bootstrap>", line 1030, in _gcd_import
  File "<frozen importlib._bootstrap>", line 1007, in _find_and_load
  File "<frozen importlib._bootstrap>", line 986, in _find_and_load_unlocked
  File "<frozen importlib._bootstrap>", line 680, in _load_unlocked
  File "<frozen importlib._bootstrap_external>", line 850, in exec_module
  File "<frozen importlib._bootstrap>", line 228, in _call_with_frames_removed
  File "/root/DataCenter/app.py", line 2, in <module>
    from AI_API.home import router as apiRouter
  File "/root/DataCenter/AI_API/home.py", line 1, in <module>
    from AI_API.gptUsage import GetGptUsage
  File "/root/DataCenter/AI_API/gptUsage.py", line 3, in <module>
    from Config import GptKey
ModuleNotFoundError: No module named 'Config'
WARNING:  StatReload detected changes in 'config.py'. Reloading...
Process SpawnProcess-9:
Traceback (most recent call last):
  File "/usr/lib64/python3.9/multiprocessing/process.py", line 315, in _bootstrap
    self.run()
  File "/usr/lib64/python3.9/multiprocessing/process.py", line 108, in run
    self._target(*self._args, **self._kwargs)
  File "/root/DataCenter/DataCenter_Venv/lib64/python3.9/site-packages/uvicorn/_subprocess.py", line 80, in subprocess_started
    target(sockets=sockets)
  File "/root/DataCenter/DataCenter_Venv/lib64/python3.9/site-packages/uvicorn/server.py", line 67, in run
    return asyncio.run(self.serve(sockets=sockets))
  File "/usr/lib64/python3.9/asyncio/runners.py", line 44, in run
    return loop.run_until_complete(main)
  File "/usr/lib64/python3.9/asyncio/base_events.py", line 647, in run_until_complete
    return future.result()
  File "/root/DataCenter/DataCenter_Venv/lib64/python3.9/site-packages/uvicorn/server.py", line 71, in serve
    await self._serve(sockets)
  File "/root/DataCenter/DataCenter_Venv/lib64/python3.9/site-packages/uvicorn/server.py", line 78, in _serve
    config.load()
  File "/root/DataCenter/DataCenter_Venv/lib64/python3.9/site-packages/uvicorn/config.py", line 436, in load
    self.loaded_app = import_from_string(self.app)
  File "/root/DataCenter/DataCenter_Venv/lib64/python3.9/site-packages/uvicorn/importer.py", line 22, in import_from_string
    raise exc from None
  File "/root/DataCenter/DataCenter_Venv/lib64/python3.9/site-packages/uvicorn/importer.py", line 19, in import_from_string
    module = importlib.import_module(module_str)
  File "/usr/lib64/python3.9/importlib/__init__.py", line 127, in import_module
    return _bootstrap._gcd_import(name[level:], package, level)
  File "<frozen importlib._bootstrap>", line 1030, in _gcd_import
  File "<frozen importlib._bootstrap>", line 1007, in _find_and_load
  File "<frozen importlib._bootstrap>", line 986, in _find_and_load_unlocked
  File "<frozen importlib._bootstrap>", line 680, in _load_unlocked
  File "<frozen importlib._bootstrap_external>", line 850, in exec_module
  File "<frozen importlib._bootstrap>", line 228, in _call_with_frames_removed
  File "/root/DataCenter/app.py", line 2, in <module>
    from AI_API.home import router as apiRouter
  File "/root/DataCenter/AI_API/home.py", line 1, in <module>
    from AI_API.gptUsage import GetGptUsage
  File "/root/DataCenter/AI_API/gptUsage.py", line 3, in <module>
    from Config import GptKey
ModuleNotFoundError: No module named 'Config'
WARNING:  StatReload detected changes in 'AI_API/gptUsage.py'. Reloading...
Process SpawnProcess-10:
Traceback (most recent call last):
  File "/usr/lib64/python3.9/multiprocessing/process.py", line 315, in _bootstrap
    self.run()
  File "/usr/lib64/python3.9/multiprocessing/process.py", line 108, in run
    self._target(*self._args, **self._kwargs)
  File "/root/DataCenter/DataCenter_Venv/lib64/python3.9/site-packages/uvicorn/_subprocess.py", line 80, in subprocess_started
    target(sockets=sockets)
  File "/root/DataCenter/DataCenter_Venv/lib64/python3.9/site-packages/uvicorn/server.py", line 67, in run
    return asyncio.run(self.serve(sockets=sockets))
  File "/usr/lib64/python3.9/asyncio/runners.py", line 44, in run
    return loop.run_until_complete(main)
  File "/usr/lib64/python3.9/asyncio/base_events.py", line 647, in run_until_complete
    return future.result()
  File "/root/DataCenter/DataCenter_Venv/lib64/python3.9/site-packages/uvicorn/server.py", line 71, in serve
    await self._serve(sockets)
  File "/root/DataCenter/DataCenter_Venv/lib64/python3.9/site-packages/uvicorn/server.py", line 78, in _serve
    config.load()
  File "/root/DataCenter/DataCenter_Venv/lib64/python3.9/site-packages/uvicorn/config.py", line 436, in load
    self.loaded_app = import_from_string(self.app)
  File "/root/DataCenter/DataCenter_Venv/lib64/python3.9/site-packages/uvicorn/importer.py", line 22, in import_from_string
    raise exc from None
  File "/root/DataCenter/DataCenter_Venv/lib64/python3.9/site-packages/uvicorn/importer.py", line 19, in import_from_string
    module = importlib.import_module(module_str)
  File "/usr/lib64/python3.9/importlib/__init__.py", line 127, in import_module
    return _bootstrap._gcd_import(name[level:], package, level)
  File "<frozen importlib._bootstrap>", line 1030, in _gcd_import
  File "<frozen importlib._bootstrap>", line 1007, in _find_and_load
  File "<frozen importlib._bootstrap>", line 986, in _find_and_load_unlocked
  File "<frozen importlib._bootstrap>", line 680, in _load_unlocked
  File "<frozen importlib._bootstrap_external>", line 850, in exec_module
  File "<frozen importlib._bootstrap>", line 228, in _call_with_frames_removed
  File "/root/DataCenter/app.py", line 2, in <module>
    from AI_API.home import router as apiRouter
  File "/root/DataCenter/AI_API/home.py", line 1, in <module>
    from AI_API.gptUsage import GetGptUsage
  File "/root/DataCenter/AI_API/gptUsage.py", line 3, in <module>
    from Config import key
ModuleNotFoundError: No module named 'Config'
WARNING:  StatReload detected changes in 'AI_API/gptUsage.py'. Reloading...
Process SpawnProcess-11:
Traceback (most recent call last):
  File "/usr/lib64/python3.9/multiprocessing/process.py", line 315, in _bootstrap
    self.run()
  File "/usr/lib64/python3.9/multiprocessing/process.py", line 108, in run
    self._target(*self._args, **self._kwargs)
  File "/root/DataCenter/DataCenter_Venv/lib64/python3.9/site-packages/uvicorn/_subprocess.py", line 80, in subprocess_started
    target(sockets=sockets)
  File "/root/DataCenter/DataCenter_Venv/lib64/python3.9/site-packages/uvicorn/server.py", line 67, in run
    return asyncio.run(self.serve(sockets=sockets))
  File "/usr/lib64/python3.9/asyncio/runners.py", line 44, in run
    return loop.run_until_complete(main)
  File "/usr/lib64/python3.9/asyncio/base_events.py", line 647, in run_until_complete
    return future.result()
  File "/root/DataCenter/DataCenter_Venv/lib64/python3.9/site-packages/uvicorn/server.py", line 71, in serve
    await self._serve(sockets)
  File "/root/DataCenter/DataCenter_Venv/lib64/python3.9/site-packages/uvicorn/server.py", line 78, in _serve
    config.load()
  File "/root/DataCenter/DataCenter_Venv/lib64/python3.9/site-packages/uvicorn/config.py", line 436, in load
    self.loaded_app = import_from_string(self.app)
  File "/root/DataCenter/DataCenter_Venv/lib64/python3.9/site-packages/uvicorn/importer.py", line 22, in import_from_string
    raise exc from None
  File "/root/DataCenter/DataCenter_Venv/lib64/python3.9/site-packages/uvicorn/importer.py", line 19, in import_from_string
    module = importlib.import_module(module_str)
  File "/usr/lib64/python3.9/importlib/__init__.py", line 127, in import_module
    return _bootstrap._gcd_import(name[level:], package, level)
  File "<frozen importlib._bootstrap>", line 1030, in _gcd_import
  File "<frozen importlib._bootstrap>", line 1007, in _find_and_load
  File "<frozen importlib._bootstrap>", line 986, in _find_and_load_unlocked
  File "<frozen importlib._bootstrap>", line 680, in _load_unlocked
  File "<frozen importlib._bootstrap_external>", line 850, in exec_module
  File "<frozen importlib._bootstrap>", line 228, in _call_with_frames_removed
  File "/root/DataCenter/app.py", line 2, in <module>
    from AI_API.home import router as apiRouter
  File "/root/DataCenter/AI_API/home.py", line 1, in <module>
    from AI_API.gptUsage import GetGptUsage
  File "/root/DataCenter/AI_API/gptUsage.py", line 3, in <module>
    from Config import key
ModuleNotFoundError: No module named 'Config'
WARNING:  StatReload detected changes in 'AI_API/gptUsage.py'. Reloading...
Process SpawnProcess-12:
Traceback (most recent call last):
  File "/usr/lib64/python3.9/multiprocessing/process.py", line 315, in _bootstrap
    self.run()
  File "/usr/lib64/python3.9/multiprocessing/process.py", line 108, in run
    self._target(*self._args, **self._kwargs)
  File "/root/DataCenter/DataCenter_Venv/lib64/python3.9/site-packages/uvicorn/_subprocess.py", line 80, in subprocess_started
    target(sockets=sockets)
  File "/root/DataCenter/DataCenter_Venv/lib64/python3.9/site-packages/uvicorn/server.py", line 67, in run
    return asyncio.run(self.serve(sockets=sockets))
  File "/usr/lib64/python3.9/asyncio/runners.py", line 44, in run
    return loop.run_until_complete(main)
  File "/usr/lib64/python3.9/asyncio/base_events.py", line 647, in run_until_complete
    return future.result()
  File "/root/DataCenter/DataCenter_Venv/lib64/python3.9/site-packages/uvicorn/server.py", line 71, in serve
    await self._serve(sockets)
  File "/root/DataCenter/DataCenter_Venv/lib64/python3.9/site-packages/uvicorn/server.py", line 78, in _serve
    config.load()
  File "/root/DataCenter/DataCenter_Venv/lib64/python3.9/site-packages/uvicorn/config.py", line 436, in load
    self.loaded_app = import_from_string(self.app)
  File "/root/DataCenter/DataCenter_Venv/lib64/python3.9/site-packages/uvicorn/importer.py", line 22, in import_from_string
    raise exc from None
  File "/root/DataCenter/DataCenter_Venv/lib64/python3.9/site-packages/uvicorn/importer.py", line 19, in import_from_string
    module = importlib.import_module(module_str)
  File "/usr/lib64/python3.9/importlib/__init__.py", line 127, in import_module
    return _bootstrap._gcd_import(name[level:], package, level)
  File "<frozen importlib._bootstrap>", line 1030, in _gcd_import
  File "<frozen importlib._bootstrap>", line 1007, in _find_and_load
  File "<frozen importlib._bootstrap>", line 986, in _find_and_load_unlocked
  File "<frozen importlib._bootstrap>", line 680, in _load_unlocked
  File "<frozen importlib._bootstrap_external>", line 850, in exec_module
  File "<frozen importlib._bootstrap>", line 228, in _call_with_frames_removed
  File "/root/DataCenter/app.py", line 2, in <module>
    from AI_API.home import router as apiRouter
  File "/root/DataCenter/AI_API/home.py", line 1, in <module>
    from AI_API.gptUsage import GetGptUsage
  File "/root/DataCenter/AI_API/gptUsage.py", line 3, in <module>
    from Config import key
ModuleNotFoundError: No module named 'Config'
WARNING:  StatReload detected changes in 'AI_API/gptUsage.py'. Reloading...
Process SpawnProcess-13:
Traceback (most recent call last):
  File "/usr/lib64/python3.9/multiprocessing/process.py", line 315, in _bootstrap
    self.run()
  File "/usr/lib64/python3.9/multiprocessing/process.py", line 108, in run
    self._target(*self._args, **self._kwargs)
  File "/root/DataCenter/DataCenter_Venv/lib64/python3.9/site-packages/uvicorn/_subprocess.py", line 80, in subprocess_started
    target(sockets=sockets)
  File "/root/DataCenter/DataCenter_Venv/lib64/python3.9/site-packages/uvicorn/server.py", line 67, in run
    return asyncio.run(self.serve(sockets=sockets))
  File "/usr/lib64/python3.9/asyncio/runners.py", line 44, in run
    return loop.run_until_complete(main)
  File "/usr/lib64/python3.9/asyncio/base_events.py", line 647, in run_until_complete
    return future.result()
  File "/root/DataCenter/DataCenter_Venv/lib64/python3.9/site-packages/uvicorn/server.py", line 71, in serve
    await self._serve(sockets)
  File "/root/DataCenter/DataCenter_Venv/lib64/python3.9/site-packages/uvicorn/server.py", line 78, in _serve
    config.load()
  File "/root/DataCenter/DataCenter_Venv/lib64/python3.9/site-packages/uvicorn/config.py", line 436, in load
    self.loaded_app = import_from_string(self.app)
  File "/root/DataCenter/DataCenter_Venv/lib64/python3.9/site-packages/uvicorn/importer.py", line 19, in import_from_string
    module = importlib.import_module(module_str)
  File "/usr/lib64/python3.9/importlib/__init__.py", line 127, in import_module
    return _bootstrap._gcd_import(name[level:], package, level)
  File "<frozen importlib._bootstrap>", line 1030, in _gcd_import
  File "<frozen importlib._bootstrap>", line 1007, in _find_and_load
  File "<frozen importlib._bootstrap>", line 986, in _find_and_load_unlocked
  File "<frozen importlib._bootstrap>", line 680, in _load_unlocked
  File "<frozen importlib._bootstrap_external>", line 850, in exec_module
  File "<frozen importlib._bootstrap>", line 228, in _call_with_frames_removed
  File "/root/DataCenter/app.py", line 2, in <module>
    from AI_API.home import router as apiRouter
  File "/root/DataCenter/AI_API/home.py", line 1, in <module>
    from AI_API.gptUsage import GetGptUsage
  File "/root/DataCenter/AI_API/gptUsage.py", line 3, in <module>
    from config import key
ImportError: cannot import name 'key' from 'config' (/root/DataCenter/config.py)
WARNING:  StatReload detected changes in 'config.py'. Reloading...
Process SpawnProcess-14:
Traceback (most recent call last):
  File "/usr/lib64/python3.9/multiprocessing/process.py", line 315, in _bootstrap
    self.run()
  File "/usr/lib64/python3.9/multiprocessing/process.py", line 108, in run
    self._target(*self._args, **self._kwargs)
  File "/root/DataCenter/DataCenter_Venv/lib64/python3.9/site-packages/uvicorn/_subprocess.py", line 80, in subprocess_started
    target(sockets=sockets)
  File "/root/DataCenter/DataCenter_Venv/lib64/python3.9/site-packages/uvicorn/server.py", line 67, in run
    return asyncio.run(self.serve(sockets=sockets))
  File "/usr/lib64/python3.9/asyncio/runners.py", line 44, in run
    return loop.run_until_complete(main)
  File "/usr/lib64/python3.9/asyncio/base_events.py", line 647, in run_until_complete
    return future.result()
  File "/root/DataCenter/DataCenter_Venv/lib64/python3.9/site-packages/uvicorn/server.py", line 71, in serve
    await self._serve(sockets)
  File "/root/DataCenter/DataCenter_Venv/lib64/python3.9/site-packages/uvicorn/server.py", line 78, in _serve
    config.load()
  File "/root/DataCenter/DataCenter_Venv/lib64/python3.9/site-packages/uvicorn/config.py", line 436, in load
    self.loaded_app = import_from_string(self.app)
  File "/root/DataCenter/DataCenter_Venv/lib64/python3.9/site-packages/uvicorn/importer.py", line 19, in import_from_string
    module = importlib.import_module(module_str)
  File "/usr/lib64/python3.9/importlib/__init__.py", line 127, in import_module
    return _bootstrap._gcd_import(name[level:], package, level)
  File "<frozen importlib._bootstrap>", line 1030, in _gcd_import
  File "<frozen importlib._bootstrap>", line 1007, in _find_and_load
  File "<frozen importlib._bootstrap>", line 986, in _find_and_load_unlocked
  File "<frozen importlib._bootstrap>", line 680, in _load_unlocked
  File "<frozen importlib._bootstrap_external>", line 850, in exec_module
  File "<frozen importlib._bootstrap>", line 228, in _call_with_frames_removed
  File "/root/DataCenter/app.py", line 2, in <module>
    from AI_API.home import router as apiRouter
  File "/root/DataCenter/AI_API/home.py", line 1, in <module>
    from AI_API.gptUsage import GetGptUsage
  File "/root/DataCenter/AI_API/gptUsage.py", line 3, in <module>
    from config import key
ImportError: cannot import name 'key' from 'config' (/root/DataCenter/config.py)
WARNING:  StatReload detected changes in 'config.py'. Reloading...
Process SpawnProcess-15:
Traceback (most recent call last):
  File "/usr/lib64/python3.9/multiprocessing/process.py", line 315, in _bootstrap
    self.run()
  File "/usr/lib64/python3.9/multiprocessing/process.py", line 108, in run
    self._target(*self._args, **self._kwargs)
  File "/root/DataCenter/DataCenter_Venv/lib64/python3.9/site-packages/uvicorn/_subprocess.py", line 80, in subprocess_started
    target(sockets=sockets)
  File "/root/DataCenter/DataCenter_Venv/lib64/python3.9/site-packages/uvicorn/server.py", line 67, in run
    return asyncio.run(self.serve(sockets=sockets))
  File "/usr/lib64/python3.9/asyncio/runners.py", line 44, in run
    return loop.run_until_complete(main)
  File "/usr/lib64/python3.9/asyncio/base_events.py", line 647, in run_until_complete
    return future.result()
  File "/root/DataCenter/DataCenter_Venv/lib64/python3.9/site-packages/uvicorn/server.py", line 71, in serve
    await self._serve(sockets)
  File "/root/DataCenter/DataCenter_Venv/lib64/python3.9/site-packages/uvicorn/server.py", line 78, in _serve
    config.load()
  File "/root/DataCenter/DataCenter_Venv/lib64/python3.9/site-packages/uvicorn/config.py", line 436, in load
    self.loaded_app = import_from_string(self.app)
  File "/root/DataCenter/DataCenter_Venv/lib64/python3.9/site-packages/uvicorn/importer.py", line 19, in import_from_string
    module = importlib.import_module(module_str)
  File "/usr/lib64/python3.9/importlib/__init__.py", line 127, in import_module
    return _bootstrap._gcd_import(name[level:], package, level)
  File "<frozen importlib._bootstrap>", line 1030, in _gcd_import
  File "<frozen importlib._bootstrap>", line 1007, in _find_and_load
  File "<frozen importlib._bootstrap>", line 986, in _find_and_load_unlocked
  File "<frozen importlib._bootstrap>", line 680, in _load_unlocked
  File "<frozen importlib._bootstrap_external>", line 850, in exec_module
  File "<frozen importlib._bootstrap>", line 228, in _call_with_frames_removed
  File "/root/DataCenter/app.py", line 2, in <module>
    from AI_API.home import router as apiRouter
  File "/root/DataCenter/AI_API/home.py", line 1, in <module>
    from AI_API.gptUsage import GetGptUsage
  File "/root/DataCenter/AI_API/gptUsage.py", line 3, in <module>
    from config import key
ImportError: cannot import name 'key' from 'config' (/root/DataCenter/config.py)
WARNING:  StatReload detected changes in 'AI_API/gptUsage.py'. Reloading...
Process SpawnProcess-16:
Traceback (most recent call last):
  File "/usr/lib64/python3.9/multiprocessing/process.py", line 315, in _bootstrap
    self.run()
  File "/usr/lib64/python3.9/multiprocessing/process.py", line 108, in run
    self._target(*self._args, **self._kwargs)
  File "/root/DataCenter/DataCenter_Venv/lib64/python3.9/site-packages/uvicorn/_subprocess.py", line 80, in subprocess_started
    target(sockets=sockets)
  File "/root/DataCenter/DataCenter_Venv/lib64/python3.9/site-packages/uvicorn/server.py", line 67, in run
    return asyncio.run(self.serve(sockets=sockets))
  File "/usr/lib64/python3.9/asyncio/runners.py", line 44, in run
    return loop.run_until_complete(main)
  File "/usr/lib64/python3.9/asyncio/base_events.py", line 647, in run_until_complete
    return future.result()
  File "/root/DataCenter/DataCenter_Venv/lib64/python3.9/site-packages/uvicorn/server.py", line 71, in serve
    await self._serve(sockets)
  File "/root/DataCenter/DataCenter_Venv/lib64/python3.9/site-packages/uvicorn/server.py", line 78, in _serve
    config.load()
  File "/root/DataCenter/DataCenter_Venv/lib64/python3.9/site-packages/uvicorn/config.py", line 436, in load
    self.loaded_app = import_from_string(self.app)
  File "/root/DataCenter/DataCenter_Venv/lib64/python3.9/site-packages/uvicorn/importer.py", line 19, in import_from_string
    module = importlib.import_module(module_str)
  File "/usr/lib64/python3.9/importlib/__init__.py", line 127, in import_module
    return _bootstrap._gcd_import(name[level:], package, level)
  File "<frozen importlib._bootstrap>", line 1030, in _gcd_import
  File "<frozen importlib._bootstrap>", line 1007, in _find_and_load
  File "<frozen importlib._bootstrap>", line 986, in _find_and_load_unlocked
  File "<frozen importlib._bootstrap>", line 680, in _load_unlocked
  File "<frozen importlib._bootstrap_external>", line 850, in exec_module
  File "<frozen importlib._bootstrap>", line 228, in _call_with_frames_removed
  File "/root/DataCenter/app.py", line 2, in <module>
    from AI_API.home import router as apiRouter
  File "/root/DataCenter/AI_API/home.py", line 1, in <module>
    from AI_API.gptUsage import GetGptUsage
  File "/root/DataCenter/AI_API/gptUsage.py", line 33, in <module>
    "Authorization": key.api ,
NameError: name 'key' is not defined
WARNING:  StatReload detected changes in 'AI_API/gptUsage.py'. Reloading...
INFO:     Started server process [40576]
INFO:     Waiting for application startup.
INFO:     Application startup complete.
INFO:     119.147.10.159:30273 - "GET /docs HTTP/1.1" 200 OK
INFO:     119.147.10.159:24270 - "GET /docs HTTP/1.1" 200 OK
WARNING:  StatReload detected changes in 'AI_API/gptUsage.py'. Reloading...
INFO:     Shutting down
INFO:     Waiting for application shutdown.
INFO:     Application shutdown complete.
INFO:     Finished server process [40576]
INFO:     Started server process [40577]
INFO:     Waiting for application startup.
INFO:     Application startup complete.
INFO:     119.147.10.159:50676 - "GET /openapi.json HTTP/1.1" 200 OK
INFO:     119.147.10.159:50676 - "GET /apiUsage HTTP/1.1" 200 OK
WARNING:  StatReload detected changes in 'config.py'. Reloading...
INFO:     Shutting down
INFO:     Waiting for application shutdown.
INFO:     Application shutdown complete.
INFO:     Finished server process [40577]
INFO:     Started server process [41670]
INFO:     Waiting for application startup.
INFO:     Application startup complete.
WARNING:  StatReload detected changes in 'AI_API/home.py'. Reloading...
INFO:     Shutting down
INFO:     Waiting for application shutdown.
INFO:     Application shutdown complete.
INFO:     Finished server process [41670]
INFO:     Started server process [41840]
INFO:     Waiting for application startup.
INFO:     Application startup complete.
